<?xml version="1.0" encoding="utf-8"?>
<!-- This URDF was automatically created by SolidWorks to URDF Exporter! Originally created by Stephen Brawner (brawner@gmail.com) 
     Commit Version: 1.6.0-4-g7f85cfe  Build Version: 1.6.7995.38578
     For more information, please see http://wiki.ros.org/sw_urdf_exporter -->
<robot
  name="simplified_arm_assembly">

    <!-- fatto io-->
    <link name="base_link"/>

    <joint name="base_to_module" type="fixed">
      <parent link="base_link"/>
      <child link="module_joint"/>
      <origin xyz="0 0 0" rpy="0 0 0"/>
    </joint>
    <!-- fatto io-->

  <link
    name="module_joint">
    <inertial>
      <origin
        xyz="0 -0.0031516 0"
        rpy="0 0 0" />
      <mass
        value="0.11481" />
      <inertia
        ixx="0.00037274"
        ixy="-3.8623E-21"
        ixz="-1.0431E-22"
        iyy="1.1022E-05"
        iyz="2.037E-21"
        izz="0.00037274" />
    </inertial>
    <visual>
      <origin
        xyz="0 0 0"
        rpy="0 0 0" />
      <geometry>
        <mesh
          filename="package://simplified_arm_assembly/meshes/module_joint.STL" />
      </geometry>
      <material
        name="">
        <color
          rgba="0.75294 0.75294 0.75294 1" />
      </material>
    </visual>
    <collision>
      <origin
        xyz="0 0 0"
        rpy="0 0 0" />
      <geometry>
        <mesh
          filename="package://simplified_arm_assembly/meshes/module_joint.STL" />
      </geometry>
    </collision>
  </link>
  <link
    name="pitch_1">
    <inertial>
      <origin
        xyz="1.3878E-17 0.00059334 -1.7347E-18"
        rpy="0 0 0" />
      <mass
        value="0.28931" />
      <inertia
        ixx="0.0002425"
        ixy="3.7269E-20"
        ixz="-2.3847E-20"
        iyy="0.00023577"
        iyz="-4.6317E-21"
        izz="0.00025759" />
    </inertial>
    <visual>
      <origin
        xyz="0 0 0"
        rpy="0 0 0" />
      <geometry>
        <mesh
          filename="package://simplified_arm_assembly/meshes/pitch_1.STL" />
      </geometry>
      <material
        name="">
        <color
          rgba="0.75294 0.75294 0.75294 1" />
      </material>
    </visual>
    <collision>
      <origin
        xyz="0 0 0"
        rpy="0 0 0" />
      <geometry>
        <mesh
          filename="package://simplified_arm_assembly/meshes/pitch_1.STL" />
      </geometry>
    </collision>
  </link>
  <joint
    name="pitch_joint_1"
    type="revolute">
    <origin
      xyz="0 0 0"
      rpy="1.5708 1.309 3.1416" />
    <parent
      link="module_joint" />
    <child
      link="pitch_1" />
    <axis
      xyz="0 0 -1" />
    <limit
      lower="-1.309"
      upper="1.309"
      effort="6"
      velocity="2" />
  </joint>
  <link
    name="roll_2">
    <inertial>
      <origin
        xyz="1.1115E-08 7.62E-08 0.014827"
        rpy="0 0 0" />
      <mass
        value="0.11865" />
      <inertia
        ixx="0.00051345"
        ixy="-2.7475E-10"
        ixz="-9.7641E-11"
        iyy="0.00051383"
        iyz="2.2625E-10"
        izz="1.0228E-05" />
    </inertial>
    <visual>
      <origin
        xyz="0 0 0"
        rpy="0 0 0" />
      <geometry>
        <mesh
          filename="package://simplified_arm_assembly/meshes/roll_2.STL" />
      </geometry>
      <material
        name="">
        <color
          rgba="0.75294 0.75294 0.75294 1" />
      </material>
    </visual>
    <collision>
      <origin
        xyz="0 0 0"
        rpy="0 0 0" />
      <geometry>
        <mesh
          filename="package://simplified_arm_assembly/meshes/roll_2.STL" />
      </geometry>
    </collision>
  </link>
  <joint
    name="roll_joint_2"
    type="revolute">
    <origin
      xyz="0 0.16147 0"
      rpy="1.5708 1.5708 0" />
    <parent
      link="pitch_1" />
    <child
      link="roll_2" />
    <axis
      xyz="0 0 1" />
    <limit
      lower="0"
      upper="6.28"
      effort="6"
      velocity="2" />
  </joint>
  <link
    name="pitch_3">
    <inertial>
      <origin
        xyz="0.060867 0.046121 -5.2042E-18"
        rpy="0 0 0" />
      <mass
        value="0.10409" />
      <inertia
        ixx="4.6765E-05"
        ixy="-9.086E-05"
        ixz="1.3572E-20"
        iyy="0.00027451"
        iyz="3.2775E-21"
        izz="0.00031255" />
    </inertial>
    <visual>
      <origin
        xyz="0 0 0"
        rpy="0 0 0" />
      <geometry>
        <mesh
          filename="package://simplified_arm_assembly/meshes/pitch_3.STL" />
      </geometry>
      <material
        name="">
        <color
          rgba="0.75294 0.75294 0.75294 1" />
      </material>
    </visual>
    <collision>
      <origin
        xyz="0 0 0"
        rpy="0 0 0" />
      <geometry>
        <mesh
          filename="package://simplified_arm_assembly/meshes/pitch_3.STL" />
      </geometry>
    </collision>
  </link>
  <joint
    name="pitch_joint_3"
    type="revolute">
    <origin
      xyz="0 0 -0.1271"
      rpy="3.1416 -1.5708 0" />
    <parent
      link="roll_2" />
    <child
      link="pitch_3" />
    <axis
      xyz="0 0 1" />
    <limit
      lower="0"
      upper="2.88"
      effort="6"
      velocity="2" />
  </joint>
  <link
    name="roll_4">
    <inertial>
      <origin
        xyz="1.9082E-17 -0.0018789 0.03054"
        rpy="0 0 0" />
      <mass
        value="0.096867" />
      <inertia
        ixx="5.2065E-05"
        ixy="-2.0065E-21"
        ixz="-6.0327E-21"
        iyy="4.9885E-05"
        iyz="2.3291E-07"
        izz="2.3052E-05" />
    </inertial>
    <visual>
      <origin
        xyz="0 0 0"
        rpy="0 0 0" />
      <geometry>
        <mesh
          filename="package://simplified_arm_assembly/meshes/roll_4.STL" />
      </geometry>
      <material
        name="">
        <color
          rgba="0.75294 0.75294 0.75294 1" />
      </material>
    </visual>
    <collision>
      <origin
        xyz="0 0 0"
        rpy="0 0 0" />
      <geometry>
        <mesh
          filename="package://simplified_arm_assembly/meshes/roll_4.STL" />
      </geometry>
    </collision>
  </link>
  <joint
    name="roll_joint_4"
    type="revolute">
    <origin
      xyz="0.15351 0.074002 0"
      rpy="3.4034 -1.5708 0" />
    <parent
      link="pitch_3" />
    <child
      link="roll_4" />
    <axis
      xyz="0 0 1" />
    <limit
      lower="0"
      upper="6.28"
      effort="3"
      velocity="1" />
  </joint>
  <link
    name="pitch_5">
    <inertial>
      <origin
        xyz="0.045311 -1.3878E-17 -3.1225E-17"
        rpy="0 0 0" />
      <mass
        value="0.056876" />
      <inertia
        ixx="1.5222E-05"
        ixy="3.2086E-21"
        ixz="2.628E-21"
        iyy="2.2881E-05"
        iyz="-6.6366E-22"
        izz="1.6114E-05" />
    </inertial>
    <visual>
      <origin
        xyz="0 0 0"
        rpy="0 0 0" />
      <geometry>
        <mesh
          filename="package://simplified_arm_assembly/meshes/pitch_5.STL" />
      </geometry>
      <material
        name="">
        <color
          rgba="0.75294 0.75294 0.75294 1" />
      </material>
    </visual>
    <collision>
      <origin
        xyz="0 0 0"
        rpy="0 0 0" />
      <geometry>
        <mesh
          filename="package://simplified_arm_assembly/meshes/pitch_5.STL" />
      </geometry>
    </collision>
  </link>
  <joint
    name="pitch_joint_5"
    type="revolute">
    <origin
      xyz="0 0 0.05447"
      rpy="3.1416 -1.5708 0" />
    <parent
      link="roll_4" />
    <child
      link="pitch_5" />
    <axis
      xyz="0 0 -1" />
    <limit
      lower="-1.57"
      upper="1.57"
      effort="3"
      velocity="1" />
  </joint>
  <link
    name="roll_6">
    <inertial>
      <origin
        xyz="7.9797E-17 0.0089729 0.056902"
        rpy="0 0 0" />
      <mass
        value="0.54009" />
      <inertia
        ixx="0.00046175"
        ixy="1.37E-19"
        ixz="1.5743E-19"
        iyy="0.0009503"
        iyz="7.6437E-06"
        izz="0.00081963" />
    </inertial>
    <visual>
      <origin
        xyz="0 0 0"
        rpy="0 0 0" />
      <geometry>
        <mesh
          filename="package://simplified_arm_assembly/meshes/roll_6.STL" />
      </geometry>
      <material
        name="">
        <color
          rgba="0.75294 0.75294 0.75294 1" />
      </material>
    </visual>
    <collision>
      <origin
        xyz="0 0 0"
        rpy="0 0 0" />
      <geometry>
        <mesh
          filename="package://simplified_arm_assembly/meshes/roll_6.STL" />
      </geometry>
    </collision>
  </link>
  <joint
    name="roll_joint_6"
    type="revolute">
    <origin
      xyz="0.065961 0 0"
      rpy="0 1.5708 0" />
    <parent
      link="pitch_5" />
    <child
      link="roll_6" />
    <axis
      xyz="0 0 -1" />
    <limit
      lower="0"
      upper="6.28"
      effort="3"
      velocity="1" />
  </joint>
</robot>